Workbook

Sheet 생산계획
A1: ◈ Monitor 생산계획
A2: =TODAY() -> 46120 | D2: CU재작업 | L2: 3월 : 166대 | M2: 알피니언 : 40까지 | P2: 일우 자재입고 확인
A3: 라인 | B3: 구분 | C3: 46112 | D3: 46113 | E3: 46114 | F3: 46115 | G3: 46116 | H3: 46117 | I3: 46118 | J3: 46119 | K3: 46120 | L3: 46121 | M3: 46122 | N3: 46123 | O3: 46124 | P3: 46125 | Q3: 46126 | R3: 46127 | S3: 46128 | T3: 46129 | U3: 46130 | V3: 46131 | W3: 46132 | X3: 46133 | Y3: 46134 | Z3: 46135 | AA3: 46136 | AB3: 46137 | AC3: 46138 | AD3: 46139 | AE3: 46140 | AF3: 46141 | AG3: 46142 | AH3: 46143 | AI3: 46144 | AJ3: 46145 | AK3: 46146 | AL3: 46147 | AM3: 46148 | AN3: 46149 | AO3: 46150 | AP3: 46151 | AQ3: 46152 | AR3: 46153 | AS3: 46154 | AT3: 46155 | AU3: 46156 | AV3: 46157 | AW3: 46158 | AX3: 46159 | AY3: 46160 | AZ3: 46161 | BA3: 46162 | BB3: 46163 | BC3: 46164 | BD3: 46165 | BE3: 46166 | BF3: 46167 | BG3: 46168 | BH3: 46169 | BI3: 46170 | BJ3: 46171 | BK3: 46172 | BL3: 46173 | BM3: 46174 | BN3: 46175 | BO3: 46176 | BP3: 46177 | BQ3: 46178 | BR3: 46179 | BS3: 46180 | BT3: 46181 | BU3: 46182 | BV3: 46183 | BW3: 46184 | BX3: 46185 | BY3: 46186 | BZ3: 46187 | CA3: 46188 | CB3: 46189 | CC3: 46190 | CD3: 46191 | CE3: 46192 | CF3: 46193 | CG3: 46194 | CH3: 46195 | CI3: 46196 | CJ3: 46197 | CK3: 46198 | CL3: 46199 | CM3: 46200 | CN3: 46201 | CO3: 46202 | CP3: 46203 | CQ3: 46204 | CR3: 46205 | CS3: 46206 | CT3: 46207 | CU3: 46208 | CV3: 46209 | CW3: 46210 | CX3: 46211 | CY3: 46212 | CZ3: 46213 | DA3: 46214 | DB3: 46215 | DC3: 46216 | DD3: 46217 | DE3: 46218 | DF3: 46219 | DG3: 46220 | DH3: 46221 | DI3: 46222 | DJ3: 46223 | DK3: 46224 | DL3: 46225 | DM3: 46226 | DN3: 46227 | DO3: 46228 | DP3: 46229 | DQ3: 46230 | DR3: 46231 | DS3: 46232 | DT3: 46233 | DU3: 46234 | DV3: 46235 | DW3: 46236 | DX3: 46237 | DY3: 46238 | DZ3: 46239 | EA3: 46240 | EB3: 46241 | EC3: 46242 | ED3: 46243 | EE3: 46244 | EF3: 46245
C4: 화 | D4: 수 | E4: 목 | F4: 금 | G4: 토 | H4: 일 | I4: 월 | J4: 화 | K4: 수 | L4: 목 | M4: 금 | N4: 토 | O4: 일 | P4: 월 | Q4: 화 | R4: 수 | S4: 목 | T4: 금 | U4: 토 | V4: 일 | W4: 월 | X4: 화 | Y4: 수 | Z4: 목 | AA4: 금 | AB4: 토 | AC4: 일 | AD4: 월 | AE4: 화 | AF4: 수 | AG4: 목 | AH4: 금 | AI4: 토 | AJ4: 일 | AK4: 월 | AL4: 화 | AM4: 수 | AN4: 목 | AO4: 금 | AP4: 토 | AQ4: 일 | AR4: 월 | AS4: 화 | AT4: 수 | AU4: 목 | AV4: 금 | AW4: 토 | AX4: 일 | AY4: 월 | AZ4: 화 | BA4: 수 | BB4: 목 | BC4: 금 | BD4: 토 | BE4: 일 | BF4: 월 | BG4: 화 | BH4: 수 | BI4: 목 | BJ4: 금 | BK4: 토 | BL4: 일 | BM4: 월 | BN4: 화 | BO4: 수 | BP4: 목 | BQ4: 금 | BR4: 토 | BS4: 일 | BT4: 월 | BU4: 화 | BV4: 수 | BW4: 목 | BX4: 금 | BY4: 토 | BZ4: 일 | CA4: 월 | CB4: 화 | CC4: 수 | CD4: 목 | CE4: 금 | CF4: 토 | CG4: 일 | CH4: 월 | CI4: 화 | CJ4: 수 | CK4: 목 | CL4: 금 | CM4: 토 | CN4: 일 | CO4: 월 | CP4: 화 | CQ4: 수 | CR4: 목 | CS4: 금 | CT4: 토 | CU4: 일 | CV4: 월 | CW4: 화 | CX4: 수 | CY4: 목 | CZ4: 금 | DA4: 토 | DB4: 일 | DC4: 월 | DD4: 화 | DE4: 수 | DF4: 목 | DG4: 금 | DH4: 토 | DI4: 일 | DJ4: 월 | DK4: 화 | DL4: 수 | DM4: 목 | DN4: 금 | DO4: 토 | DP4: 일 | DQ4: 월 | DR4: 화 | DS4: 수 | DT4: 목 | DU4: 금 | DV4: 토 | DW4: 일 | DX4: 월 | DY4: 화 | DZ4: 수 | EA4: 목 | EB4: 금 | EC4: 토 | ED4: 일 | EE4: 월 | EF4: 화
A5: 조립계획 | B5: P/N | C5: TMP6133009 | F5: TMP7133001 | L5: TMP6133002 | M5: TMP6133002 | P5: TMP6104TDAP_VE_KM | Q5: TMP6104TDAP_VE_KM | S5: TMP6133009 | T5: TMP6133009 | W5: TMP6104TDAP_VE_KM | X5: TMP6104TDAP_VE_KM | Y5: TMP6121001 | Z5: TMP6121001 | AA5: TMP6121001 | AD5: TMP6133001 | AE5: TMP6133009 | AF5: TMP6133009 | AG5: TMP6133009 | AH5: 휴무 | AM5: TMP6133009 | AN5: TMP6133009 | AO5: TMP6133009
B6: 모델명 | C6: =IFERROR(VLOOKUP(C5,'[1]M 기준정보'!$B$5:$C$49936,2,0),"") -> S6133-NT(NEW TREE) | D6: =IFERROR(VLOOKUP(D5,'[1]M 기준정보'!$B$5:$C$49936,2,0),"") | E6: =IFERROR(VLOOKUP(E5,'[1]M 기준정보'!$B$5:$C$49936,2,0),"") | F6: =IFERROR(VLOOKUP(F5,'[1]M 기준정보'!$B$5:$C$49936,2,0),"") -> EPS7133 스타벅스 탁상用 | G6: =IFERROR(VLOOKUP(G5,'[1]M 기준정보'!$B$5:$C$49936,2,0),"") | H6: =IFERROR(VLOOKUP(H5,'[1]M 기준정보'!$B$5:$C$49936,2,0),"") | I6: =IFERROR(VLOOKUP(I5,'[1]M 기준정보'!$B$5:$C$49936,2,0),"") | J6: =IFERROR(VLOOKUP(J5,'[1]M 기준정보'!$B$5:$C$49936,2,0),"") | ... EF6: =IFERROR(VLOOKUP(EF5,'[1]M 기준정보'!$B$5:$C$49936,2,0),"")
B7: 조립수 | C7: 20 | F7: 16 | L7: 20 | M7: 20 | P7: 20 | Q7: 20 | S7: 26 | T7: 20 | W7: 25 | X7: 20 | Y7: 20 | Z7: 20 | AA7: 20 | AD7: 4 | AE7: 20 | AF7: 20 | AG7: 20 | AM7: 20 | AN7: 20 | AO7: 20
B8: 출하계획 | F8: 4/13 30대 | L8: 4/17 40대 | P8: 4/17 40대 | S8: 4/24 46대 | W8: 4/24 45대 | AD8: 4/30 4대 | AE8: 5/8 60대 | AM8: 5/15 60대
B9: MH | C9: =IFERROR(VLOOKUP(C5,'[1]M 기준정보'!$B$5:$F$49936,5,0)*생산계획!C7,"") -> 7.2 | D9: =IFERROR(VLOOKUP(D5,'[1]M 기준정보'!$B$5:$F$49936,5,0)*생산계획!D7,"") | E9: =IFERROR(VLOOKUP(E5,'[1]M 기준정보'!$B$5:$F$49936,5,0)*생산계획!E7,"") | F9: =IFERROR(VLOOKUP(F5,'[1]M 기준정보'!$B$5:$F$49936,5,0)*생산계획!F7,"") -> 11.2 | G9: =IFERROR(VLOOKUP(G5,'[1]M 기준정보'!$B$5:$F$49936,5,0)*생산계획!G7,"") | H9: =IFERROR(VLOOKUP(H5,'[1]M 기준정보'!$B$5:$F$49936,5,0)*생산계획!H7,"") | I9: =IFERROR(VLOOKUP(I5,'[1]M 기준정보'!$B$5:$F$49936,5,0)*생산계획!I7,"") | J9: =IFERROR(VLOOKUP(J5,'[1]M 기준정보'!$B$5:$F$49936,5,0)*생산계획!J7,"") | ... EF9: =IFERROR(VLOOKUP(EF5,'[1]M 기준정보'!$B$5:$F$49936,5,0)*생산계획!EF7,"")
B10: P/N | C10: TMP6104TU005 | D10: TMO1115TI401 | F10: TMP7133002 | T10: TMO6150NI403
B11: 모델명 | C11: =IFERROR(VLOOKUP(C10,'[1]M 기준정보'!$B$5:$C$49936,2,0),"") -> LEO2.0 MONITOR FRU | D11: =IFERROR(VLOOKUP(D10,'[1]M 기준정보'!$B$5:$C$49936,2,0),"") -> AM-1115 BLACK SK향(구형 F/W) | E11: =IFERROR(VLOOKUP(E10,'[1]M 기준정보'!$B$5:$C$49936,2,0),"") | F11: =IFERROR(VLOOKUP(F10,'[1]M 기준정보'!$B$5:$C$49936,2,0),"") -> EPS7133 스타벅스 벽걸이用 | G11: =IFERROR(VLOOKUP(G10,'[1]M 기준정보'!$B$5:$C$49936,2,0),"") | H11: =IFERROR(VLOOKUP(H10,'[1]M 기준정보'!$B$5:$C$49936,2,0),"") | I11: =IFERROR(VLOOKUP(I10,'[1]M 기준정보'!$B$5:$C$49936,2,0),"") | J11: =IFERROR(VLOOKUP(J10,'[1]M 기준정보'!$B$5:$C$49936,2,0),"") | ... EF11: =IFERROR(VLOOKUP(EF10,'[1]M 기준정보'!$B$5:$C$49936,2,0),"")
B12: 조립수 | C12: 3 | D12: 8 | F12: 3 | T12: 5
B13: 출하계획 | C13: 4/3 3대 | D13: 4/6 8대 | F13: 4/13 3대 | T13: 4/24 5대
B14: MH | C14: =IFERROR(VLOOKUP(C10,'[1]M 기준정보'!$B$5:$F$49936,5,0)*생산계획!C12,"") -> 1.62 | D14: =IFERROR(VLOOKUP(D10,'[1]M 기준정보'!$B$5:$F$49936,5,0)*생산계획!D12,"") -> 3.84 | E14: =IFERROR(VLOOKUP(E10,'[1]M 기준정보'!$B$5:$F$49936,5,0)*생산계획!E12,"") | F14: =IFERROR(VLOOKUP(F10,'[1]M 기준정보'!$B$5:$F$49936,5,0)*생산계획!F12,"") -> 2.1 | G14: =IFERROR(VLOOKUP(G10,'[1]M 기준정보'!$B$5:$F$49936,5,0)*생산계획!G12,"") | H14: =IFERROR(VLOOKUP(H10,'[1]M 기준정보'!$B$5:$F$49936,5,0)*생산계획!H12,"") | I14: =IFERROR(VLOOKUP(I10,'[1]M 기준정보'!$B$5:$F$49936,5,0)*생산계획!I12,"") | J14: =IFERROR(VLOOKUP(J10,'[1]M 기준정보'!$B$5:$F$49936,5,0)*생산계획!J12,"") | ... EF14: =IFERROR(VLOOKUP(EF10,'[1]M 기준정보'!$B$5:$F$49936,5,0)*생산계획!EF12,"")
B15: P/N | C15: TMP6000NI403 | D15: TMP6000NI403 | E15: TMS7150006 | F15: TMS7150017 | I15: TMS9150008 | J15: TMS9150008 | K15: TMS9150008 | L15: TMS9150008 | M15: TMP6000NI402 | P15: TMS7150012 | Q15: TMS7150012 | R15: TMP6000NI403 | S15: TMP6000NI403 | T15: TMO6150TI403 | W15: TMP6000NI403 | Z15: TMO1115TI401 | AD15: TMP6000NI403 | AE15: TMP6000NI403
B16: 모델명 | C16: =IFERROR(VLOOKUP(C15,'[1]M 기준정보'!$B$5:$C$49936,2,0),"") -> SST6000LD | D16: =IFERROR(VLOOKUP(D15,'[1]M 기준정보'!$B$5:$C$49936,2,0),"") -> SST6000LD | E16: =IFERROR(VLOOKUP(E15,'[1]M 기준정보'!$B$5:$C$49936,2,0),"") -> EPS7150 DUAL [ i5 7세대, 15" 슈마커향] | F16: =IFERROR(VLOOKUP(F15,'[1]M 기준정보'!$B$5:$C$49936,2,0),"") -> EPS7150-11G(i5) DUAL RAM 16G (무선랜 ×) | G16: =IFERROR(VLOOKUP(G15,'[1]M 기준정보'!$B$5:$C$49936,2,0),"") | H16: =IFERROR(VLOOKUP(H15,'[1]M 기준정보'!$B$5:$C$49936,2,0),"") | I16: =IFERROR(VLOOKUP(I15,'[1]M 기준정보'!$B$5:$C$49936,2,0),"") -> T20i (i3-12세대) DUAL ,PP211[이마트24] | J16: =IFERROR(VLOOKUP(J15,'[1]M 기준정보'!$B$5:$C$49936,2,0),"") -> T20i (i3-12세대) DUAL ,PP211[이마트24] | ... EF16: =IFERROR(VLOOKUP(EF15,'[1]M 기준정보'!$B$5:$C$49936,2,0),"")
B17: 조립수 | C17: 60 | D17: 60 | E17: 1 | F17: 1 | I17: 15 | J17: 25 | K17: 30 | L17: 40 | M17: 32 | P17: 20 | Q17: 20 | R17: 50 | S17: 50 | T17: 5 | W17: 50 | Z17: 12 | AD17: 50 | AE17: 50
B18: 출하계획 | C18: 4/3 50대 | D18: 4/14 50대 | E18: 4/6 1대 [MST0001003] | F18: 4/6 1대 [MST0001001] | I18: 4/15 70대 (영업20260312-1) | J18: 4/15 70대 (영업20260312-1) | K18: 4/15 70대 (영업20260312-1) | L18: 4/15 70대 (영업20260312-1) | M18: 4/16 32대 | P18: 4/21 40대 (영업20260319-4) | R18: 4/20 50대 | S18: 4/23 50대 | T18: 4/24 5대 | W18: 4/27 50대 | Z18: 4/27 12대
B19: MH | C19: =IFERROR(VLOOKUP(C15,'[1]M 기준정보'!$B$5:$F$49936,5,0)*생산계획!C17,"") -> 19.2 | D19: =IFERROR(VLOOKUP(D15,'[1]M 기준정보'!$B$5:$F$49936,5,0)*생산계획!D17,"") -> 19.2 | E19: =IFERROR(VLOOKUP(E15,'[1]M 기준정보'!$B$5:$F$49936,5,0)*생산계획!E17,"") -> 1.65 | F19: =IFERROR(VLOOKUP(F15,'[1]M 기준정보'!$B$5:$F$49936,5,0)*생산계획!F17,"") -> 1.65 | G19: =IFERROR(VLOOKUP(G15,'[1]M 기준정보'!$B$5:$F$49936,5,0)*생산계획!G17,"") | H19: =IFERROR(VLOOKUP(H15,'[1]M 기준정보'!$B$5:$F$49936,5,0)*생산계획!H17,"") | I19: =IFERROR(VLOOKUP(I15,'[1]M 기준정보'!$B$5:$F$49936,5,0)*생산계획!I17,"") -> 24.75 | J19: =IFERROR(VLOOKUP(J15,'[1]M 기준정보'!$B$5:$F$49936,5,0)*생산계획!J17,"") -> 41.25 | ... EF19: =IFERROR(VLOOKUP(EF15,'[1]M 기준정보'!$B$5:$F$49936,5,0)*생산계획!EF17,"")
B20: P/N | C20: TMS7150014 | D20: TMS7150014 | E20: TMS7150014 | F20: TMS7150014 | I20: TMS7150014 | J20: TMS7150014 | K20: TMS7150014 | L20: TMP6000NI403 | M20: TMP6000NI403 | P20: TMS7150014 | Q20: TMS7150014 | R20: TMS7150014 | S20: TMS7150014 | T20: TMS7150014 | W20: TMS7150014 | X20: TMS7150014 | Y20: TMS7150014 | Z20: TMS7150014 | AA20: TMS7150014 | AD20: TMS7150014 | AE20: TMS7150014 | AF20: TMS7150014 | AG20: TMS7150014
B21: 모델명 | C21: =IFERROR(VLOOKUP(C20,'[1]M 기준정보'!$B$5:$C$49936,2,0),"") -> CPS7150 BGF(CU향) POS | D21: =IFERROR(VLOOKUP(D20,'[1]M 기준정보'!$B$5:$C$49936,2,0),"") -> CPS7150 BGF(CU향) POS | E21: =IFERROR(VLOOKUP(E20,'[1]M 기준정보'!$B$5:$C$49936,2,0),"") -> CPS7150 BGF(CU향) POS | F21: =IFERROR(VLOOKUP(F20,'[1]M 기준정보'!$B$5:$C$49936,2,0),"") -> CPS7150 BGF(CU향) POS | G21: =IFERROR(VLOOKUP(G20,'[1]M 기준정보'!$B$5:$C$49936,2,0),"") | H21: =IFERROR(VLOOKUP(H20,'[1]M 기준정보'!$B$5:$C$49936,2,0),"") | I21: =IFERROR(VLOOKUP(I20,'[1]M 기준정보'!$B$5:$C$49936,2,0),"") -> CPS7150 BGF(CU향) POS | J21: =IFERROR(VLOOKUP(J20,'[1]M 기준정보'!$B$5:$C$49936,2,0),"") -> CPS7150 BGF(CU향) POS | ... EF21: =IFERROR(VLOOKUP(EF20,'[1]M 기준정보'!$B$5:$C$49936,2,0),"")
B22: 조립수 | C22: 8 | D22: 24 | E22: 15 | F22: 21 | I22: 15 | J22: 7 | K22: 20 | L22: 50 | M22: 50 | P22: 20 | Q22: 20 | R22: 20 | S22: 20 | T22: 20 | W22: 20 | X22: 20 | Y22: 20 | Z22: 20 | AA22: 20 | AD22: 20 | AE22: 20 | AF22: 20 | AG22: 20
B23: 출하계획 | L23: 4/13 50대 | M23: 4/16 50대 | T23: 4/20 65대 (영업20260312-1)
B24: MH | C24: =IFERROR(VLOOKUP(C20,'[1]M 기준정보'!$B$5:$F$49936,5,0)*생산계획!C22,"") -> 10 | D24: =IFERROR(VLOOKUP(D20,'[1]M 기준정보'!$B$5:$F$49936,5,0)*생산계획!D22,"") -> 30 | E24: =IFERROR(VLOOKUP(E20,'[1]M 기준정보'!$B$5:$F$49936,5,0)*생산계획!E22,"") -> 18.75 | F24: =IFERROR(VLOOKUP(F20,'[1]M 기준정보'!$B$5:$F$49936,5,0)*생산계획!F22,"") -> 26.25 | G24: =IFERROR(VLOOKUP(G20,'[1]M 기준정보'!$B$5:$F$49936,5,0)*생산계획!G22,"") | H24: =IFERROR(VLOOKUP(H20,'[1]M 기준정보'!$B$5:$F$49936,5,0)*생산계획!H22,"") | I24: =IFERROR(VLOOKUP(I20,'[1]M 기준정보'!$B$5:$F$49936,5,0)*생산계획!I22,"") -> 18.75 | J24: =IFERROR(VLOOKUP(J20,'[1]M 기준정보'!$B$5:$F$49936,5,0)*생산계획!J22,"") -> 8.75 | ... EF24: =IFERROR(VLOOKUP(EF20,'[1]M 기준정보'!$B$5:$F$49936,5,0)*생산계획!EF22,"")
A26: 포장계획 | B26: P/N | C26: TMS7150014 | D26: TMS7150014 | E26: TMS7150014 | F26: TMS7150014 | I26: TMS7150014 | J26: TMS7150014 | K26: TMP7133001 | L26: TMS7150014 | M26: TMS7150014 | P26: TMS9150008 | Q26: TMS7150014 | R26: TMS7150014 | S26: TMP6133002 | T26: TMS7150012 | W26: TMP6000NI403 | Z26: TMP6104TDAP_VE_KM | AF26: TMP6133001 | AN26: TMP6133009 | AU26: TMP6133009
B27: 모델 | C27: =IFERROR(VLOOKUP(C26,'[1]M 기준정보'!$B$5:$C$49936,2,0),"") -> CPS7150 BGF(CU향) POS | D27: =IFERROR(VLOOKUP(D26,'[1]M 기준정보'!$B$5:$C$49936,2,0),"") -> CPS7150 BGF(CU향) POS | E27: =IFERROR(VLOOKUP(E26,'[1]M 기준정보'!$B$5:$C$49936,2,0),"") -> CPS7150 BGF(CU향) POS | F27: =IFERROR(VLOOKUP(F26,'[1]M 기준정보'!$B$5:$C$49936,2,0),"") -> CPS7150 BGF(CU향) POS | G27: =IFERROR(VLOOKUP(G26,'[1]M 기준정보'!$B$5:$C$49936,2,0),"") | H27: =IFERROR(VLOOKUP(H26,'[1]M 기준정보'!$B$5:$C$49936,2,0),"") | I27: =IFERROR(VLOOKUP(I26,'[1]M 기준정보'!$B$5:$C$49936,2,0),"") -> CPS7150 BGF(CU향) POS | J27: =IFERROR(VLOOKUP(J26,'[1]M 기준정보'!$B$5:$C$49936,2,0),"") -> CPS7150 BGF(CU향) POS | ... EF27: =IFERROR(VLOOKUP(EF26,'[1]M 기준정보'!$B$5:$C$49936,2,0),"")
B28: 포장수 | C28: 출하 4/3 20 | D28: 출하 4/3 5 | E28: 출하 4/3 26 | F28: 출하 4/6 27 | I28: 출하 4/9 20 | J28: 출하 4/17 16 (75대) | K28: 출하 4/13 16 | L28: 출하 4/17 30 (75대) | M28: 출하 4/17 30 (75대) | P28: 출하 4/15 70 | Q28: 출하 4/17 30 | R28: 출하 4/17 30 | S28: 출하 4/17 40 | T28: 출하 4/21 40 | W28: 출하 4/23 50 | Z28: 출하 4/24 45 | AF28: 출하 4/30 4 | AN28: 출하 5/8 60 | AU28: 출하 5/15 60
C29: =RIGHT(C28,3) -> 20 | D29: =RIGHT(D28,3) -> 3 5 | E29: =RIGHT(E28,3) -> 26 | F29: =RIGHT(F28,3) -> 27 | G29: =RIGHT(G28,3) | H29: =RIGHT(H28,3) | I29: =RIGHT(I28,3) -> 20 | J29: =RIGHT(J28,3) -> 5대) | ... EF29: =RIGHT(EF28,3)
B30: MH | C30: =IFERROR(VLOOKUP(C26,'[1]M 기준정보'!$B$5:$H$49936,6,0)*C29,"") -> 8 | D30: =IFERROR(VLOOKUP(D26,'[1]M 기준정보'!$B$5:$H$49936,6,0)*D29,"") | E30: =IFERROR(VLOOKUP(E26,'[1]M 기준정보'!$B$5:$H$49936,6,0)*E29,"") -> 10.4 | F30: =IFERROR(VLOOKUP(F26,'[1]M 기준정보'!$B$5:$H$49936,6,0)*F29,"") -> 10.8 | G30: =IFERROR(VLOOKUP(G26,'[1]M 기준정보'!$B$5:$H$49936,6,0)*G29,"") | H30: =IFERROR(VLOOKUP(H26,'[1]M 기준정보'!$B$5:$H$49936,6,0)*H29,"") | I30: =IFERROR(VLOOKUP(I26,'[1]M 기준정보'!$B$5:$H$49936,6,0)*I29,"") -> 8 | J30: =IFERROR(VLOOKUP(J26,'[1]M 기준정보'!$B$5:$H$49936,6,0)*J29,"") | ... EF30: =IFERROR(VLOOKUP(EF26,'[1]M 기준정보'!$B$5:$H$49936,6,0)*EF29,"")
B31: P/N | D31: TMP6000NI403 | E31: TMP6133009 | F31: TMO1115TI401 | I31: TMS7150017 | J31: TMP6000NI403 | K31: TMP7133002 | L31: TMO3115001 | M31: TMP6000NI403 | Q31: TMP6000NI403 | S31: TMP6104TDAP_VE_KM | T31: TMP6000NI403 | Z31: TMP6133009
B32: 모델 | C32: =IFERROR(VLOOKUP(C31,'[1]M 기준정보'!$B$5:$C$49936,2,0),"") | D32: =IFERROR(VLOOKUP(D31,'[1]M 기준정보'!$B$5:$C$49936,2,0),"") -> SST6000LD | E32: =IFERROR(VLOOKUP(E31,'[1]M 기준정보'!$B$5:$C$49936,2,0),"") -> S6133-NT(NEW TREE) | F32: =IFERROR(VLOOKUP(F31,'[1]M 기준정보'!$B$5:$C$49936,2,0),"") -> AM-1115 BLACK SK향(구형 F/W) | G32: =IFERROR(VLOOKUP(G31,'[1]M 기준정보'!$B$5:$C$49936,2,0),"") | H32: =IFERROR(VLOOKUP(H31,'[1]M 기준정보'!$B$5:$C$49936,2,0),"") | I32: =IFERROR(VLOOKUP(I31,'[1]M 기준정보'!$B$5:$C$49936,2,0),"") -> EPS7150-11G(i5) DUAL RAM 16G (무선랜 ×) | J32: =IFERROR(VLOOKUP(J31,'[1]M 기준정보'!$B$5:$C$49936,2,0),"") -> SST6000LD | ... EF32: =IFERROR(VLOOKUP(EF31,'[1]M 기준정보'!$B$5:$C$49936,2,0),"")
B33: 포장수 | D33: 출하 4/1 50 | E33: 출하 4/3 60 | F33: 출하 4/6 8 | I33: 출하 4/6 1 [MST0001001] | J33: 출하 4/7 50 | K33: 출하 4/13 3 | L33: 출하 4/16 100 | M33: 출하 4/13 50 | Q33: 출하 4/16 50 | S33: 출하 4/17 40 | T33: 출하 4/20 50 | Z33: 출하 4/24 40
C34: =RIGHT(C33,3) | D34: =RIGHT(D33,3) -> 50 | E34: =RIGHT(E33,3) -> 60 | F34: =RIGHT(F33,3) -> 6 8 | G34: =RIGHT(G33,3) | H34: =RIGHT(H33,3) | I34: =RIGHT(I33,3) -> 01] | J34: =RIGHT(J33,3) -> 50 | ... EF34: =RIGHT(EF33,3)
B35: MH | C35: =IFERROR(VLOOKUP(C31,'[1]M 기준정보'!$B$5:$H$49936,6,0)*C34,"") | D35: =IFERROR(VLOOKUP(D31,'[1]M 기준정보'!$B$5:$H$49936,6,0)*D34,"") -> 2.5 | E35: =IFERROR(VLOOKUP(E31,'[1]M 기준정보'!$B$5:$H$49936,6,0)*E34,"") -> 4.8 | F35: =IFERROR(VLOOKUP(F31,'[1]M 기준정보'!$B$5:$H$49936,6,0)*F34,"") | G35: =IFERROR(VLOOKUP(G31,'[1]M 기준정보'!$B$5:$H$49936,6,0)*G34,"") | H35: =IFERROR(VLOOKUP(H31,'[1]M 기준정보'!$B$5:$H$49936,6,0)*H34,"") | I35: =IFERROR(VLOOKUP(I31,'[1]M 기준정보'!$B$5:$H$49936,6,0)*I34,"") | J35: =IFERROR(VLOOKUP(J31,'[1]M 기준정보'!$B$5:$H$49936,6,0)*J34,"") -> 2.5 | ... EF35: =IFERROR(VLOOKUP(EF31,'[1]M 기준정보'!$B$5:$H$49936,6,0)*EF34,"")
B36: P/N | E36: TMP6133002 | F36: TMS7150013 | J36: TMS7150006 | K36: TMS9150008 | Z36: TMP6133010
B37: 모델 | C37: =IFERROR(VLOOKUP(C36,'[1]M 기준정보'!$B$5:$C$49936,2,0),"") | D37: =IFERROR(VLOOKUP(D36,'[1]M 기준정보'!$B$5:$C$49936,2,0),"") | E37: =IFERROR(VLOOKUP(E36,'[1]M 기준정보'!$B$5:$C$49936,2,0),"") -> S6133 GRIFFIN [13.3"] [Junifer] | F37: =IFERROR(VLOOKUP(F36,'[1]M 기준정보'!$B$5:$C$49936,2,0),"") -> EPS7150-11G(i5) DUAL ASSY[팜마트] | G37: =IFERROR(VLOOKUP(G36,'[1]M 기준정보'!$B$5:$C$49936,2,0),"") | H37: =IFERROR(VLOOKUP(H36,'[1]M 기준정보'!$B$5:$C$49936,2,0),"") | I37: =IFERROR(VLOOKUP(I36,'[1]M 기준정보'!$B$5:$C$49936,2,0),"") | J37: =IFERROR(VLOOKUP(J36,'[1]M 기준정보'!$B$5:$C$49936,2,0),"") -> EPS7150 DUAL [ i5 7세대, 15" 슈마커향] | ... EF37: =IFERROR(VLOOKUP(EF36,'[1]M 기준정보'!$B$5:$C$49936,2,0),"")
B38: 포장수 | E38: 출하 4/3 20 | F38: 출하 4/8 8 | J38: 출하 4/6 1 [MST0001003] | K38: 출하 4/9 40 | Z38: 출하 4/24 6
C39: =RIGHT(C38,3) | D39: =RIGHT(D38,3) | E39: =RIGHT(E38,3) -> 20 | F39: =RIGHT(F38,3) -> 8 8 | G39: =RIGHT(G38,3) | H39: =RIGHT(H38,3) | I39: =RIGHT(I38,3) | J39: =RIGHT(J38,3) -> 03] | ... EF39: =RIGHT(EF38,3)
B40: MH | C40: =IFERROR(VLOOKUP(C36,'[1]M 기준정보'!$B$5:$H$49936,6,0)*C39,"") | D40: =IFERROR(VLOOKUP(D36,'[1]M 기준정보'!$B$5:$H$49936,6,0)*D39,"") | E40: =IFERROR(VLOOKUP(E36,'[1]M 기준정보'!$B$5:$H$49936,6,0)*E39,"") -> 1.6 | F40: =IFERROR(VLOOKUP(F36,'[1]M 기준정보'!$B$5:$H$49936,6,0)*F39,"") | G40: =IFERROR(VLOOKUP(G36,'[1]M 기준정보'!$B$5:$H$49936,6,0)*G39,"") | H40: =IFERROR(VLOOKUP(H36,'[1]M 기준정보'!$B$5:$H$49936,6,0)*H39,"") | I40: =IFERROR(VLOOKUP(I36,'[1]M 기준정보'!$B$5:$H$49936,6,0)*I39,"") | J40: =IFERROR(VLOOKUP(J36,'[1]M 기준정보'!$B$5:$H$49936,6,0)*J39,"") | ... EF40: =IFERROR(VLOOKUP(EF36,'[1]M 기준정보'!$B$5:$H$49936,6,0)*EF39,"")
B41: P/N | E41: TMP6000NI403
...
